{"stats": {"errors": 0, "failures": 17, "passes": 0, "skipped": 0, "encoding": "UTF-8", "total": 17}, "results": [{"classname": "index_test:DerivativeRules", "name": "test_df_dx_3xy", "time": 0.0002193450927734375, "type": "failure", "errtype": "builtins.AssertionError", "message": "None != 3", "tb": "Traceback (most recent call last):\n  File \"/opt/conda/lib/python3.6/unittest/case.py\", line 59, in testPartExecutor\n    yield\n  File \"/opt/conda/lib/python3.6/unittest/case.py\", line 605, in run\n    testMethod()\n  File \"/home/nt591/partial-derivatives-lab-data-science-intro-000/test/index_test.py\", line 56, in test_df_dx_3xy\n    self.assertEqual(df_dx_3xy(2, 1), 3)\n  File \"/opt/conda/lib/python3.6/unittest/case.py\", line 829, in assertEqual\n    assertion_func(first, second, msg=msg)\n  File \"/opt/conda/lib/python3.6/unittest/case.py\", line 822, in _baseAssertEqual\n    raise self.failureException(msg)\nAssertionError: None != 3\n"}, {"classname": "index_test:DerivativeRules", "name": "test_df_dx_when_y_equals_nine", "time": 0.00014638900756835938, "type": "failure", "errtype": "builtins.AssertionError", "message": "None != 27", "tb": "Traceback (most recent call last):\n  File \"/opt/conda/lib/python3.6/unittest/case.py\", line 59, in testPartExecutor\n    yield\n  File \"/opt/conda/lib/python3.6/unittest/case.py\", line 605, in run\n    testMethod()\n  File \"/home/nt591/partial-derivatives-lab-data-science-intro-000/test/index_test.py\", line 53, in test_df_dx_when_y_equals_nine\n    self.assertEqual(df_dx_when_y_equals_nine(), 27)\n  File \"/opt/conda/lib/python3.6/unittest/case.py\", line 829, in assertEqual\n    assertion_func(first, second, msg=msg)\n  File \"/opt/conda/lib/python3.6/unittest/case.py\", line 822, in _baseAssertEqual\n    raise self.failureException(msg)\nAssertionError: None != 27\n"}, {"classname": "index_test:DerivativeRules", "name": "test_df_dx_when_y_equals_one", "time": 0.00015854835510253906, "type": "failure", "errtype": "builtins.AssertionError", "message": "None != 3", "tb": "Traceback (most recent call last):\n  File \"/opt/conda/lib/python3.6/unittest/case.py\", line 59, in testPartExecutor\n    yield\n  File \"/opt/conda/lib/python3.6/unittest/case.py\", line 605, in run\n    testMethod()\n  File \"/home/nt591/partial-derivatives-lab-data-science-intro-000/test/index_test.py\", line 44, in test_df_dx_when_y_equals_one\n    self.assertEqual(df_dx_when_y_equals_one(), 3)\n  File \"/opt/conda/lib/python3.6/unittest/case.py\", line 829, in assertEqual\n    assertion_func(first, second, msg=msg)\n  File \"/opt/conda/lib/python3.6/unittest/case.py\", line 822, in _baseAssertEqual\n    raise self.failureException(msg)\nAssertionError: None != 3\n"}, {"classname": "index_test:DerivativeRules", "name": "test_df_dx_when_y_equals_six", "time": 9.584426879882812e-05, "type": "failure", "errtype": "builtins.AssertionError", "message": "None != 18", "tb": "Traceback (most recent call last):\n  File \"/opt/conda/lib/python3.6/unittest/case.py\", line 59, in testPartExecutor\n    yield\n  File \"/opt/conda/lib/python3.6/unittest/case.py\", line 605, in run\n    testMethod()\n  File \"/home/nt591/partial-derivatives-lab-data-science-intro-000/test/index_test.py\", line 50, in test_df_dx_when_y_equals_six\n    self.assertEqual(df_dx_when_y_equals_six(), 18)\n  File \"/opt/conda/lib/python3.6/unittest/case.py\", line 829, in assertEqual\n    assertion_func(first, second, msg=msg)\n  File \"/opt/conda/lib/python3.6/unittest/case.py\", line 822, in _baseAssertEqual\n    raise self.failureException(msg)\nAssertionError: None != 18\n"}, {"classname": "index_test:DerivativeRules", "name": "test_df_dx_when_y_equals_three", "time": 0.00010466575622558594, "type": "failure", "errtype": "builtins.AssertionError", "message": "None != 9", "tb": "Traceback (most recent call last):\n  File \"/opt/conda/lib/python3.6/unittest/case.py\", line 59, in testPartExecutor\n    yield\n  File \"/opt/conda/lib/python3.6/unittest/case.py\", line 605, in run\n    testMethod()\n  File \"/home/nt591/partial-derivatives-lab-data-science-intro-000/test/index_test.py\", line 47, in test_df_dx_when_y_equals_three\n    self.assertEqual(df_dx_when_y_equals_three(), 9)\n  File \"/opt/conda/lib/python3.6/unittest/case.py\", line 829, in assertEqual\n    assertion_func(first, second, msg=msg)\n  File \"/opt/conda/lib/python3.6/unittest/case.py\", line 822, in _baseAssertEqual\n    raise self.failureException(msg)\nAssertionError: None != 9\n"}, {"classname": "index_test:DerivativeRules", "name": "test_df_dy", "time": 0.00010132789611816406, "type": "failure", "errtype": "builtins.AssertionError", "message": "None != [(4, 2, 0), (1, 0, 0)]", "tb": "Traceback (most recent call last):\n  File \"/opt/conda/lib/python3.6/unittest/case.py\", line 59, in testPartExecutor\n    yield\n  File \"/opt/conda/lib/python3.6/unittest/case.py\", line 605, in run\n    testMethod()\n  File \"/home/nt591/partial-derivatives-lab-data-science-intro-000/test/index_test.py\", line 82, in test_df_dy\n    self.assertEqual(df_dy(four_x_squared_y_plus_three_x_plus_y), [(4, 2, 0), (1, 0, 0)])\n  File \"/opt/conda/lib/python3.6/unittest/case.py\", line 829, in assertEqual\n    assertion_func(first, second, msg=msg)\n  File \"/opt/conda/lib/python3.6/unittest/case.py\", line 822, in _baseAssertEqual\n    raise self.failureException(msg)\nAssertionError: None != [(4, 2, 0), (1, 0, 0)]\n"}, {"classname": "index_test:DerivativeRules", "name": "test_multivariable_output_at", "time": 8.797645568847656e-05, "type": "failure", "errtype": "builtins.AssertionError", "message": "None != 8", "tb": "Traceback (most recent call last):\n  File \"/opt/conda/lib/python3.6/unittest/case.py\", line 59, in testPartExecutor\n    yield\n  File \"/opt/conda/lib/python3.6/unittest/case.py\", line 605, in run\n    testMethod()\n  File \"/home/nt591/partial-derivatives-lab-data-science-intro-000/test/index_test.py\", line 63, in test_multivariable_output_at\n    self.assertEqual(multivariable_output_at(four_x_squared_y_plus_three_x_plus_y, 1, 1), 8)\n  File \"/opt/conda/lib/python3.6/unittest/case.py\", line 829, in assertEqual\n    assertion_func(first, second, msg=msg)\n  File \"/opt/conda/lib/python3.6/unittest/case.py\", line 822, in _baseAssertEqual\n    raise self.failureException(msg)\nAssertionError: None != 8\n"}, {"classname": "index_test:DerivativeRules", "name": "test_term_df_dx", "time": 8.916854858398438e-05, "type": "failure", "errtype": "builtins.AssertionError", "message": "None != (8, 1, 1)", "tb": "Traceback (most recent call last):\n  File \"/opt/conda/lib/python3.6/unittest/case.py\", line 59, in testPartExecutor\n    yield\n  File \"/opt/conda/lib/python3.6/unittest/case.py\", line 605, in run\n    testMethod()\n  File \"/home/nt591/partial-derivatives-lab-data-science-intro-000/test/index_test.py\", line 69, in test_term_df_dx\n    self.assertEqual(term_df_dx(four_x_squared_y), (8, 1, 1))\n  File \"/opt/conda/lib/python3.6/unittest/case.py\", line 829, in assertEqual\n    assertion_func(first, second, msg=msg)\n  File \"/opt/conda/lib/python3.6/unittest/case.py\", line 822, in _baseAssertEqual\n    raise self.failureException(msg)\nAssertionError: None != (8, 1, 1)\n"}, {"classname": "index_test:DerivativeRules", "name": "test_term_df_dy", "time": 9.1552734375e-05, "type": "failure", "errtype": "builtins.AssertionError", "message": "None != (4, 2, 0)", "tb": "Traceback (most recent call last):\n  File \"/opt/conda/lib/python3.6/unittest/case.py\", line 59, in testPartExecutor\n    yield\n  File \"/opt/conda/lib/python3.6/unittest/case.py\", line 605, in run\n    testMethod()\n  File \"/home/nt591/partial-derivatives-lab-data-science-intro-000/test/index_test.py\", line 75, in test_term_df_dy\n    self.assertEqual(term_df_dy(four_x_squared_y), (4, 2, 0))\n  File \"/opt/conda/lib/python3.6/unittest/case.py\", line 829, in assertEqual\n    assertion_func(first, second, msg=msg)\n  File \"/opt/conda/lib/python3.6/unittest/case.py\", line 822, in _baseAssertEqual\n    raise self.failureException(msg)\nAssertionError: None != (4, 2, 0)\n"}, {"classname": "index_test:DerivativeRules", "name": "test_three_x_y_at_nine", "time": 9.298324584960938e-05, "type": "failure", "errtype": "builtins.AssertionError", "message": "None != 54", "tb": "Traceback (most recent call last):\n  File \"/opt/conda/lib/python3.6/unittest/case.py\", line 59, in testPartExecutor\n    yield\n  File \"/opt/conda/lib/python3.6/unittest/case.py\", line 605, in run\n    testMethod()\n  File \"/home/nt591/partial-derivatives-lab-data-science-intro-000/test/index_test.py\", line 18, in test_three_x_y_at_nine\n    self.assertEqual(three_x_y_at_nine(2), 54)\n  File \"/opt/conda/lib/python3.6/unittest/case.py\", line 829, in assertEqual\n    assertion_func(first, second, msg=msg)\n  File \"/opt/conda/lib/python3.6/unittest/case.py\", line 822, in _baseAssertEqual\n    raise self.failureException(msg)\nAssertionError: None != 54\n"}, {"classname": "index_test:DerivativeRules", "name": "test_three_x_y_at_one", "time": 0.00010275840759277344, "type": "failure", "errtype": "builtins.AssertionError", "message": "None != 9", "tb": "Traceback (most recent call last):\n  File \"/opt/conda/lib/python3.6/unittest/case.py\", line 59, in testPartExecutor\n    yield\n  File \"/opt/conda/lib/python3.6/unittest/case.py\", line 605, in run\n    testMethod()\n  File \"/home/nt591/partial-derivatives-lab-data-science-intro-000/test/index_test.py\", line 9, in test_three_x_y_at_one\n    self.assertEqual(three_x_y_at_one(3), 9)\n  File \"/opt/conda/lib/python3.6/unittest/case.py\", line 829, in assertEqual\n    assertion_func(first, second, msg=msg)\n  File \"/opt/conda/lib/python3.6/unittest/case.py\", line 822, in _baseAssertEqual\n    raise self.failureException(msg)\nAssertionError: None != 9\n"}, {"classname": "index_test:DerivativeRules", "name": "test_three_x_y_at_six", "time": 9.72747802734375e-05, "type": "failure", "errtype": "builtins.AssertionError", "message": "None != 18", "tb": "Traceback (most recent call last):\n  File \"/opt/conda/lib/python3.6/unittest/case.py\", line 59, in testPartExecutor\n    yield\n  File \"/opt/conda/lib/python3.6/unittest/case.py\", line 605, in run\n    testMethod()\n  File \"/home/nt591/partial-derivatives-lab-data-science-intro-000/test/index_test.py\", line 15, in test_three_x_y_at_six\n    self.assertEqual(three_x_y_at_six(1), 18)\n  File \"/opt/conda/lib/python3.6/unittest/case.py\", line 829, in assertEqual\n    assertion_func(first, second, msg=msg)\n  File \"/opt/conda/lib/python3.6/unittest/case.py\", line 822, in _baseAssertEqual\n    raise self.failureException(msg)\nAssertionError: None != 18\n"}, {"classname": "index_test:DerivativeRules", "name": "test_three_x_y_at_three", "time": 0.0001342296600341797, "type": "failure", "errtype": "builtins.AssertionError", "message": "None != 27", "tb": "Traceback (most recent call last):\n  File \"/opt/conda/lib/python3.6/unittest/case.py\", line 59, in testPartExecutor\n    yield\n  File \"/opt/conda/lib/python3.6/unittest/case.py\", line 605, in run\n    testMethod()\n  File \"/home/nt591/partial-derivatives-lab-data-science-intro-000/test/index_test.py\", line 12, in test_three_x_y_at_three\n    self.assertEqual(three_x_y_at_three(3), 27)\n  File \"/opt/conda/lib/python3.6/unittest/case.py\", line 829, in assertEqual\n    assertion_func(first, second, msg=msg)\n  File \"/opt/conda/lib/python3.6/unittest/case.py\", line 822, in _baseAssertEqual\n    raise self.failureException(msg)\nAssertionError: None != 27\n"}, {"classname": "index_test:DerivativeRules", "name": "test_y_values_for_at_nine", "time": 0.00015163421630859375, "type": "failure", "errtype": "builtins.AssertionError", "message": "None != [0, 27, 54, 81, 108]", "tb": "Traceback (most recent call last):\n  File \"/opt/conda/lib/python3.6/unittest/case.py\", line 59, in testPartExecutor\n    yield\n  File \"/opt/conda/lib/python3.6/unittest/case.py\", line 605, in run\n    testMethod()\n  File \"/home/nt591/partial-derivatives-lab-data-science-intro-000/test/index_test.py\", line 40, in test_y_values_for_at_nine\n    self.assertEqual(y_values_for_at_nine(zero_to_four), [0, 27, 54, 81, 108])\n  File \"/opt/conda/lib/python3.6/unittest/case.py\", line 829, in assertEqual\n    assertion_func(first, second, msg=msg)\n  File \"/opt/conda/lib/python3.6/unittest/case.py\", line 822, in _baseAssertEqual\n    raise self.failureException(msg)\nAssertionError: None != [0, 27, 54, 81, 108]\n"}, {"classname": "index_test:DerivativeRules", "name": "test_y_values_for_at_one", "time": 0.00012993812561035156, "type": "failure", "errtype": "builtins.AssertionError", "message": "None != [0, 3, 6, 9, 12, 15, 18, 21, 24, 27, 30]", "tb": "Traceback (most recent call last):\n  File \"/opt/conda/lib/python3.6/unittest/case.py\", line 59, in testPartExecutor\n    yield\n  File \"/opt/conda/lib/python3.6/unittest/case.py\", line 605, in run\n    testMethod()\n  File \"/home/nt591/partial-derivatives-lab-data-science-intro-000/test/index_test.py\", line 23, in test_y_values_for_at_one\n    self.assertEqual(y_values_for_at_one(zero_to_ten), [0, 3, 6, 9, 12, 15, 18, 21, 24, 27, 30])\n  File \"/opt/conda/lib/python3.6/unittest/case.py\", line 829, in assertEqual\n    assertion_func(first, second, msg=msg)\n  File \"/opt/conda/lib/python3.6/unittest/case.py\", line 822, in _baseAssertEqual\n    raise self.failureException(msg)\nAssertionError: None != [0, 3, 6, 9, 12, 15, 18, 21, 24, 27, 30]\n"}, {"classname": "index_test:DerivativeRules", "name": "test_y_values_for_at_six", "time": 0.000118255615234375, "type": "failure", "errtype": "builtins.AssertionError", "message": "None != [0, 18, 36, 54, 72]", "tb": "Traceback (most recent call last):\n  File \"/opt/conda/lib/python3.6/unittest/case.py\", line 59, in testPartExecutor\n    yield\n  File \"/opt/conda/lib/python3.6/unittest/case.py\", line 605, in run\n    testMethod()\n  File \"/home/nt591/partial-derivatives-lab-data-science-intro-000/test/index_test.py\", line 34, in test_y_values_for_at_six\n    self.assertEqual(y_values_for_at_six(zero_to_four), [0, 18, 36, 54, 72])\n  File \"/opt/conda/lib/python3.6/unittest/case.py\", line 829, in assertEqual\n    assertion_func(first, second, msg=msg)\n  File \"/opt/conda/lib/python3.6/unittest/case.py\", line 822, in _baseAssertEqual\n    raise self.failureException(msg)\nAssertionError: None != [0, 18, 36, 54, 72]\n"}, {"classname": "index_test:DerivativeRules", "name": "test_y_values_for_at_three", "time": 9.250640869140625e-05, "type": "failure", "errtype": "builtins.AssertionError", "message": "None != [0, 9, 18, 27, 36]", "tb": "Traceback (most recent call last):\n  File \"/opt/conda/lib/python3.6/unittest/case.py\", line 59, in testPartExecutor\n    yield\n  File \"/opt/conda/lib/python3.6/unittest/case.py\", line 605, in run\n    testMethod()\n  File \"/home/nt591/partial-derivatives-lab-data-science-intro-000/test/index_test.py\", line 28, in test_y_values_for_at_three\n    self.assertEqual(y_values_for_at_three(zero_to_four), [0, 9, 18, 27, 36])\n  File \"/opt/conda/lib/python3.6/unittest/case.py\", line 829, in assertEqual\n    assertion_func(first, second, msg=msg)\n  File \"/opt/conda/lib/python3.6/unittest/case.py\", line 822, in _baseAssertEqual\n    raise self.failureException(msg)\nAssertionError: None != [0, 9, 18, 27, 36]\n"}]}